Workbook
Name CFADS_NCA_Series: 'Data Input'!$H$16:$H$45
Name Debt_Build: 'Data Input'!$A$94:$C$101
Name DSCR_Schedule: 'Data Input'!$A$16:$D$45
Name Liquidity_Block: 'Data Input'!$B$124:$B$128
Name P90_Block: 'Data Input'!$B$54:$B$57
Name PLCR_LLCR_Inputs: 'Data Input'!$B$68:$B$74
Name Project_CFO: 'Data Input'!$B$118
Name Sheet_Parameters: 'Data Input'!$B$5:$B$8
Name TNW_Build: 'Data Input'!$B$106:$B$113

Sheet Read Me
A1: CREDIT RATING SIMULATOR — KEY INPUT TEMPLATE 2 | WORKED REFERENCE COPY: TP-2 MID WIND | v3.0
A2: Blocks B (Cash-flow Adequacy) and C (Financial Strength) — Core Rating Criteria v2.0
A3: Version 3.0 — 30 July 2026. Supersedes v2.0 and v1.0. Governing document: Core Rating Criteria v3.0, Sections 10.2, 14 (Appendix A — enumerations) and 15 (Appendix B — field dictionary). Companion: Key Input Template 1 v3.0 (Blocks A and D, and notching inputs).
A5: Purpose
A6: This workbook captures only the Key Outputs the Python scoring engine needs from the project's full financial model — it is not the model itself. Keep the full working model separately. THE EXTRACTION PIPELINE READS THE "DATA INPUT" SHEET, addressed through the named ranges listed at step 2; sheet names, row labels and named ranges must not be changed. v2.0 described the extraction contract against the legacy B - Cashflow and C - Financial layout while a v3.0-era Data Input sheet had already replaced it as the entry surface, and the workbook simultaneously called itself v2.0 and v3.0 (QA finding M16).
A8: Legend
A9: Yellow cells = enter a value here (hardcoded input from your financial model).
A10: Blue-shaded cells = calculated automatically by formula; do not overtype.
A11: Blue text = a number you typed in; black text = a formula; green text = a link to another sheet in this workbook.
A13: How to use
A14: 1. Complete every yellow cell on the 'Data Input' sheet — this single sheet replaces the former 'B - Cashflow' and 'C - Financial' data-entry sheets. The legacy sheets are still present and feed the Validation sheet and the scoring engine, but they now pull their values from 'Data Input' automatically.
A15: 2. The DSCR schedule on 'B - Cashflow' now runs to 30 debt years (rows 9 to 38) and every dependent formula reads the whole block, so a longer tenor needs no formula change — just fill the additional rows. In v1.0 the MIN and AVERAGE formulas were hard-ranged to rows 9 to 23 while this Read Me told users to extend the schedule for longer tenors, so any added row was silently excluded from both ratios. That is fixed.
... A47: WORKED REFERENCE COPY — TP-2 MID WIND. This is NOT a blank template. Every figure is invented and belongs to reference project TP-2 in Credit Rating Simulator Test Fixtures v3.0. It exists so the application can be validated end to end: upload this workbook and the matching completed Key Input Template 1, run the assessment, and check the result against the TP-2 column of the "Test Projects" sheet — raw 84.5, one notch for an Adequate DISCOM offtaker, post-notching 77.5, band BB, no cap, d = 0.5, confidence Moderate. DO NOT USE IT FOR A LIVE ASSESSMENT and do not place it in the same searchable knowledge base as one. Sheet protection is deliberately OFF here so every derived cell can be inspected.

Sheet Data Input
A1: CREDIT RATING SIMULATOR — DATA INPUT (Blocks B & C) | Version 3.0 — 30 July 2026
A2: Yellow cells = enter a value. Blue cells = calculated automatically — locked, do not overtype. ALL PERCENTAGES ARE DECIMAL FRACTIONS: enter 0.9700 for 97%, never 97 (CORE Section 9.6). All figures in the currency/unit stated in row 5. Field names in braces are CORE Appendix B names. THIS IS THE ONLY DATA-ENTRY SHEET.
A4: A — SHEET PARAMETERS
A5: Currency / unit used throughout this workbook | B5: INR Lakh
A6: Calculation date (DD-MM-YYYY) | B6: 2026-07-30
A7: Technology type ▸ enter exactly: Wind / Solar PV / Solar + Wind Hybrid | B7: Wind
A8: Merchant exposure > DERIVED, not entered. The engine computes 1 - contracted_revenue_share from Template 1 Section A.2 (CORE V13). Shown here read-only for the Score Preview.
A9: Threshold set applied (CORE Section 4.0) ◀ auto | B9: =IF(B7="Wind","Set W",IF(B7="Solar PV","Set S",IF(B7="Solar + Wind Hybrid","Set H","CHECK B7"))) -> Set W
A10: Merchant adjustment to all DSCR thresholds (CORE Section 4.0) ◀ auto | B10: =IF(B8>0.25,0.2,0) -> 0
A11: Where derived merchant exposure exceeds 0.2500, CORE Section 4.0 adds 0.20x to every DSCR TIER threshold in the selected set. The Score Preview applies that shift automatically. The COVERAGE FLOOR at 1.00x is absolute and is NEVER shifted (CORE Section 4.1, QA finding M1).
A13: B — BLOCK B: CASH-FLOW ADEQUACY (CORE Section 4.0–4.4, 9.1–9.2, 9.5) | Max 35 points
A14: B1. DSCR Schedule — P90 basis (30 debt years; fill only the years that apply)
A15: Debt Year | B15: CFADS | C15: Interest | D15: Principal Repayment | E15: Debt Service (Int+Prin) | F15: DSCR | H15: CFADS — net-cash-accrual route | I15: Per-period variance (V6)
A16: Year 1 | B16: 3869.38 | C16: 1960 | D16: 927.6 | E16: =IF(COUNT(C16:D16)=0,"",C16+D16) -> 2887.6 | F16: =IF(OR(E16="",E16=0),"",B16/E16) -> 1.3399986 | I16: =IF(OR(B16="",H16=""),"",ABS(H16-B16)/B16)
A17: Year 2 | B17: 4107.4 | C17: 1869.1 | D17: 983.26 | E17: =IF(COUNT(C17:D17)=0,"",C17+D17) -> 2852.36 | F17: =IF(OR(E17="",E17=0),"",B17/E17) -> 1.4400006 | I17: =IF(OR(B17="",H17=""),"",ABS(H17-B17)/B17)
A18: Year 3 | B18: 4096.57 | C18: 1772.74 | D18: 1038.91 | E18: =IF(COUNT(C18:D18)=0,"",C18+D18) -> 2811.65 | F18: =IF(OR(E18="",E18=0),"",B18/E18) -> 1.4569986 | I18: =IF(OR(B18="",H18=""),"",ABS(H18-B18)/B18)
A19: Year 4 | B19: 4076.33 | C19: 1670.92 | D19: 1094.57 | E19: =IF(COUNT(C19:D19)=0,"",C19+D19) -> 2765.49 | F19: =IF(OR(E19="",E19=0),"",B19/E19) -> 1.4739992 | I19: =IF(OR(B19="",H19=""),"",ABS(H19-B19)/B19)
A20: Year 5 | B20: 4046.4 | C20: 1563.65 | D20: 1150.23 | E20: =IF(COUNT(C20:D20)=0,"",C20+D20) -> 2713.88 | F20: =IF(OR(E20="",E20=0),"",B20/E20) -> 1.4910018 | I20: =IF(OR(B20="",H20=""),"",ABS(H20-B20)/B20)
A21: Year 6 | B21: 4006.47 | C21: 1450.93 | D21: 1205.88 | E21: =IF(COUNT(C21:D21)=0,"",C21+D21) -> 2656.81 | F21: =IF(OR(E21="",E21=0),"",B21/E21) -> 1.5080002 | I21: =IF(OR(B21="",H21=""),"",ABS(H21-B21)/B21)
A22: Year 7 | B22: 3956.31 | C22: 1332.76 | D22: 1261.54 | E22: =IF(COUNT(C22:D22)=0,"",C22+D22) -> 2594.3 | F22: =IF(OR(E22="",E22=0),"",B22/E22) -> 1.525001 | I22: =IF(OR(B22="",H22=""),"",ABS(H22-B22)/B22)
A23: Year 8 | B23: 3895.57 | C23: 1209.12 | D23: 1317.19 | E23: =IF(COUNT(C23:D23)=0,"",C23+D23) -> 2526.31 | F23: =IF(OR(E23="",E23=0),"",B23/E23) -> 1.542 | I23: =IF(OR(B23="",H23=""),"",ABS(H23-B23)/B23)
A24: Year 9 | B24: 3824.06 | C24: 1080.04 | D24: 1372.85 | E24: =IF(COUNT(C24:D24)=0,"",C24+D24) -> 2452.89 | F24: =IF(OR(E24="",E24=0),"",B24/E24) -> 1.5590018 | I24: =IF(OR(B24="",H24=""),"",ABS(H24-B24)/B24)
A25: Year 10 | B25: 3741.44 | C25: 945.5 | D25: 1428.51 | E25: =IF(COUNT(C25:D25)=0,"",C25+D25) -> 2374.01 | F25: =IF(OR(E25="",E25=0),"",B25/E25) -> 1.5760001 | I25: =IF(OR(B25="",H25=""),"",ABS(H25-B25)/B25)
A26: Year 11 | B26: 3647.44 | C26: 805.51 | D26: 1484.16 | E26: =IF(COUNT(C26:D26)=0,"",C26+D26) -> 2289.67 | F26: =IF(OR(E26="",E26=0),"",B26/E26) -> 1.5929981 | I26: =IF(OR(B26="",H26=""),"",ABS(H26-B26)/B26)
A27: Year 12 | B27: 3541.81 | C27: 660.06 | D27: 1539.82 | E27: =IF(COUNT(C27:D27)=0,"",C27+D27) -> 2199.88 | F27: =IF(OR(E27="",E27=0),"",B27/E27) -> 1.6100015 | I27: =IF(OR(B27="",H27=""),"",ABS(H27-B27)/B27)
... A29: Year 14 | B29: 6079.41 | C29: 352.8 | D29: 3600 | E29: =IF(COUNT(C29:D29)=0,"",C29+D29) -> 3952.8 | F29: =IF(OR(E29="",E29=0),"",B29/E29) -> 1.5380009 | I29: =IF(OR(B29="",H29=""),"",ABS(H29-B29)/B29)
A30: Year 15 | E30: =IF(COUNT(C30:D30)=0,"",C30+D30) | F30: =IF(OR(E30="",E30=0),"",B30/E30) | I30: =IF(OR(B30="",H30=""),"",ABS(H30-B30)/B30)
A31: Year 16 | E31: =IF(COUNT(C31:D31)=0,"",C31+D31) | F31: =IF(OR(E31="",E31=0),"",B31/E31) | I31: =IF(OR(B31="",H31=""),"",ABS(H31-B31)/B31)
A32: Year 17 | E32: =IF(COUNT(C32:D32)=0,"",C32+D32) | F32: =IF(OR(E32="",E32=0),"",B32/E32) | I32: =IF(OR(B32="",H32=""),"",ABS(H32-B32)/B32)
A33: Year 18 | E33: =IF(COUNT(C33:D33)=0,"",C33+D33) | F33: =IF(OR(E33="",E33=0),"",B33/E33) | I33: =IF(OR(B33="",H33=""),"",ABS(H33-B33)/B33)
A34: Year 19 | E34: =IF(COUNT(C34:D34)=0,"",C34+D34) | F34: =IF(OR(E34="",E34=0),"",B34/E34) | I34: =IF(OR(B34="",H34=""),"",ABS(H34-B34)/B34)
A35: Year 20 | E35: =IF(COUNT(C35:D35)=0,"",C35+D35) | F35: =IF(OR(E35="",E35=0),"",B35/E35) | I35: =IF(OR(B35="",H35=""),"",ABS(H35-B35)/B35)
A36: Year 21 | E36: =IF(COUNT(C36:D36)=0,"",C36+D36) | F36: =IF(OR(E36="",E36=0),"",B36/E36) | I36: =IF(OR(B36="",H36=""),"",ABS(H36-B36)/B36)
A37: Year 22 | E37: =IF(COUNT(C37:D37)=0,"",C37+D37) | F37: =IF(OR(E37="",E37=0),"",B37/E37) | I37: =IF(OR(B37="",H37=""),"",ABS(H37-B37)/B37)
A38: Year 23 | E38: =IF(COUNT(C38:D38)=0,"",C38+D38) | F38: =IF(OR(E38="",E38=0),"",B38/E38) | I38: =IF(OR(B38="",H38=""),"",ABS(H38-B38)/B38)
A39: Year 24 | E39: =IF(COUNT(C39:D39)=0,"",C39+D39) | F39: =IF(OR(E39="",E39=0),"",B39/E39) | I39: =IF(OR(B39="",H39=""),"",ABS(H39-B39)/B39)
A40: Year 25 | E40: =IF(COUNT(C40:D40)=0,"",C40+D40) | F40: =IF(OR(E40="",E40=0),"",B40/E40) | I40: =IF(OR(B40="",H40=""),"",ABS(H40-B40)/B40)
A41: Year 26 | E41: =IF(COUNT(C41:D41)=0,"",C41+D41) | F41: =IF(OR(E41="",E41=0),"",B41/E41) | I41: =IF(OR(B41="",H41=""),"",ABS(H41-B41)/B41)
... A45: Year 30 | E45: =IF(COUNT(C45:D45)=0,"",C45+D45) | F45: =IF(OR(E45="",E45=0),"",B45/E45) | I45: =IF(OR(B45="",H45=""),"",ABS(H45-B45)/B45)
A47: B2. Derived Coverage Ratios ◀ calculated automatically
...

Sheet B - Cashflow
A1: BLOCK B — CASH-FLOW ADEQUACY: KEY OUTPUTS
A2: Feeds Core Rating Criteria v2.0 Sections 4.0–4.4, 9.1–9.2 and 9.5. Version 3.0 — 30 July 2026.
A3: READ-ONLY MIRROR. Every value on this sheet is a formula reading the "Data Input" sheet. ENTER ALL DATA ON "DATA INPUT". This sheet is retained only so anyone familiar with the v1.0/v2.0 layout can find their bearings; it is not an entry surface and is protected accordingly.
A4: Sheet parameters
A5: Currency / unit used throughout this sheet | B5: ='Data Input'!B5 -> INR Lakh
A6: Calculation date (DD-MM-YYYY) | B6: ='Data Input'!B6 -> 2026-07-30
A7: Technology type — enter exactly: Wind / Solar PV / Solar + Wind Hybrid | B7: ='Data Input'!B7 -> Wind
A8: Merchant exposure > DERIVED, not entered. The engine computes 1 - contracted_revenue_share from Template 1 Section A.2 (CORE V13). Shown here read-only for the Score Preview. | B8: ='Data Input'!B8 -> 0
A9: Threshold set applied (CORE Section 4.0) | B9: =IF(B7="Wind","Set W",IF(B7="Solar PV","Set S",IF(B7="Solar + Wind Hybrid","Set H","CHECK B7"))) -> Set W
A10: Merchant adjustment to all DSCR thresholds (CORE Section 4.0) | B10: =IF(B8>0.25,0.2,0) -> 0
A11: Where derived merchant exposure exceeds 0.2500, CORE Section 4.0 adds 0.20x to every DSCR TIER threshold in the selected set. The Score Preview applies that shift automatically. The COVERAGE FLOOR at 1.00x is absolute and is NEVER shifted (CORE Section 4.1, QA finding M1).
A13: DSCR schedule — P90 basis (30 debt years; fill only the years that apply)
A14: Debt Year | B14: CFADS | C14: Interest | D14: Principal Repayment | E14: Debt Service (Int+Prin) | F14: DSCR
A15: Year 1 | B15: ='Data Input'!B16 -> 3869.38 | C15: ='Data Input'!C16 -> 1960 | D15: ='Data Input'!D16 -> 927.6 | E15: =IF(COUNT(C15:D15)=0,"",C15+D15) -> 2887.6 | F15: =IF(OR(E15="",E15=0),"",B15/E15) -> 1.3399986
A16: Year 2 | B16: ='Data Input'!B17 -> 4107.4 | C16: ='Data Input'!C17 -> 1869.1 | D16: ='Data Input'!D17 -> 983.26 | E16: =IF(COUNT(C16:D16)=0,"",C16+D16) -> 2852.36 | F16: =IF(OR(E16="",E16=0),"",B16/E16) -> 1.4400006
A17: Year 3 | B17: ='Data Input'!B18 -> 4096.57 | C17: ='Data Input'!C18 -> 1772.74 | D17: ='Data Input'!D18 -> 1038.91 | E17: =IF(COUNT(C17:D17)=0,"",C17+D17) -> 2811.65 | F17: =IF(OR(E17="",E17=0),"",B17/E17) -> 1.4569986
A18: Year 4 | B18: ='Data Input'!B19 -> 4076.33 | C18: ='Data Input'!C19 -> 1670.92 | D18: ='Data Input'!D19 -> 1094.57 | E18: =IF(COUNT(C18:D18)=0,"",C18+D18) -> 2765.49 | F18: =IF(OR(E18="",E18=0),"",B18/E18) -> 1.4739992
A19: Year 5 | B19: ='Data Input'!B20 -> 4046.4 | C19: ='Data Input'!C20 -> 1563.65 | D19: ='Data Input'!D20 -> 1150.23 | E19: =IF(COUNT(C19:D19)=0,"",C19+D19) -> 2713.88 | F19: =IF(OR(E19="",E19=0),"",B19/E19) -> 1.4910018
A20: Year 6 | B20: ='Data Input'!B21 -> 4006.47 | C20: ='Data Input'!C21 -> 1450.93 | D20: ='Data Input'!D21 -> 1205.88 | E20: =IF(COUNT(C20:D20)=0,"",C20+D20) -> 2656.81 | F20: =IF(OR(E20="",E20=0),"",B20/E20) -> 1.5080002
A21: Year 7 | B21: ='Data Input'!B22 -> 3956.31 | C21: ='Data Input'!C22 -> 1332.76 | D21: ='Data Input'!D22 -> 1261.54 | E21: =IF(COUNT(C21:D21)=0,"",C21+D21) -> 2594.3 | F21: =IF(OR(E21="",E21=0),"",B21/E21) -> 1.525001
A22: Year 8 | B22: ='Data Input'!B23 -> 3895.57 | C22: ='Data Input'!C23 -> 1209.12 | D22: ='Data Input'!D23 -> 1317.19 | E22: =IF(COUNT(C22:D22)=0,"",C22+D22) -> 2526.31 | F22: =IF(OR(E22="",E22=0),"",B22/E22) -> 1.542
A23: Year 9 | B23: ='Data Input'!B24 -> 3824.06 | C23: ='Data Input'!C24 -> 1080.04 | D23: ='Data Input'!D24 -> 1372.85 | E23: =IF(COUNT(C23:D23)=0,"",C23+D23) -> 2452.89 | F23: =IF(OR(E23="",E23=0),"",B23/E23) -> 1.5590018
A24: Year 10 | B24: ='Data Input'!B25 -> 3741.44 | C24: ='Data Input'!C25 -> 945.5 | D24: ='Data Input'!D25 -> 1428.51 | E24: =IF(COUNT(C24:D24)=0,"",C24+D24) -> 2374.01 | F24: =IF(OR(E24="",E24=0),"",B24/E24) -> 1.5760001
A25: Year 11 | B25: ='Data Input'!B26 -> 3647.44 | C25: ='Data Input'!C26 -> 805.51 | D25: ='Data Input'!D26 -> 1484.16 | E25: =IF(COUNT(C25:D25)=0,"",C25+D25) -> 2289.67 | F25: =IF(OR(E25="",E25=0),"",B25/E25) -> 1.5929981
A26: Year 12 | B26: ='Data Input'!B27 -> 3541.81 | C26: ='Data Input'!C27 -> 660.06 | D26: ='Data Input'!D27 -> 1539.82 | E26: =IF(COUNT(C26:D26)=0,"",C26+D26) -> 2199.88 | F26: =IF(OR(E26="",E26=0),"",B26/E26) -> 1.6100015
... A44: Year 30 | B44: ='Data Input'!B45 -> 0 | C44: ='Data Input'!C45 -> 0 | D44: ='Data Input'!D45 -> 0 | E44: =IF(COUNT(C44:D44)=0,"",C44+D44) -> 0 | F44: =IF(OR(E44="",E44=0),"",B44/E44)
A46: Derived coverage ratios
A47: Minimum DSCR (P90 basis) | B47: =IF(COUNT(F15:F44)=0,"",MIN(F15:F44)) -> 1.3399986
A48: Average DSCR (P90 basis) — arithmetic mean of annual DSCRs, per CORE Section 4.2 | B48: =IF(COUNT(F15:F44)=0,"",AVERAGE(F15:F44)) -> 1.5200002
A49: Debt years populated | B49: =COUNT(F15:F44) -> 14
A50: Both formulas above read the full 30-year block, so extending the schedule needs no formula change. In v1.0 they were hard-ranged to the first 15 years while the Read Me instructed users to extend the schedule for longer tenors, so any added year was silently excluded from both ratios.
A52: P90 attestation — mandatory before Block B can be scored (CORE Section 9.5)
A53: P90 annual PLF / generation estimate (%) | B53: ='Data Input'!B54 -> 0.31
A54: Basis of the CFADS schedule > the only permitted value is: Attested as P90 | B54: ='Data Input'!B55 -> Attested as P90
A55: Resource study relied on (consultant and report date) | B55: ='Data Input'!B56 -> Vortex P90 wind resource assessment, 05-02-2026
A56: Preparer name and date of attestation | B56: ='Data Input'!B57 -> S. Tirumela, 30-07-2026
A57: P90 attestation status | B57: ='Data Input'!B58 -> Satisfied
A58: CORE v3.0 Section 9.5: attestation is the only route; the derivation route is withdrawn. All four attestation fields are critical inputs.
A60: CFADS reconciliation — direct build against net-cash-accrual build (CORE Section 9.1)
A61: Optional. Complete only if your model produces CFADS by the net-cash-accrual route. The two routes must agree within 2% for every period (validation rule V6).
...

Sheet C - Financial
A1: BLOCK C — FINANCIAL STRENGTH: KEY OUTPUTS
A2: Feeds Core Rating Criteria v2.0 Sections 5.1–5.3, 9.3 and 9.7 (non-double-counting rule). Version 3.0 — 30 July 2026.
A3: Currency / unit used throughout this sheet | B3: INR Lakh
A4: READ-ONLY MIRROR. Every value on this sheet is a formula reading the "Data Input" sheet. ENTER ALL DATA ON "DATA INPUT". This sheet is retained only so anyone familiar with the v1.0/v2.0 layout can find their bearings; it is not an entry surface and is protected accordingly.
A5: Total Debt build — itemise by instrument (CORE Section 9.3)
A6: Enter each instrument separately. The equity-treatment column decides whether an instrument is Total Debt or Tangible Net Worth. An instrument qualifies as equity only if all three conditions at CORE Section 9.3 hold: mandatorily and fully convertible or not repayable before final maturity of the rated debt; no cash coupon ahead of scheduled debt service; and contractual subordination to the rated debt. Enter Debt or Equity in column C. v1.0 left Total Debt, Adjusted Debt and Tangible Net Worth undefined, and CCD-heavy structures are common in Indian renewables — the classification moves Sections 5.1 and 5.2 by whole tiers.
A7: Instrument | B7: Amount | C7: Treatment (Debt / Equity)
A8: Rupee term loans | B8: ='Data Input'!B94 -> 20000 | C8: ='Data Input'!C94 -> Debt
A9: Foreign-currency term loans | B9: ='Data Input'!B95 -> 1500 | C9: ='Data Input'!C95 -> Debt
A10: Non-convertible debentures | B10: ='Data Input'!B96 -> 1000 | C10: ='Data Input'!C96 -> Equity
A11: Drawn working-capital borrowings (incl. cash credit, drawn LCs) | B11: ='Data Input'!B97 -> 0 | C11: ='Data Input'!C97 -> 0
A12: Finance and capital lease liabilities | B12: ='Data Input'!B98 -> 0 | C12: ='Data Input'!C98 -> 0
A13: Subordinated sponsor loans | B13: ='Data Input'!B99 -> 0 | C13: ='Data Input'!C99 -> 0
A14: Compulsorily convertible debentures (CCDs) | B14: ='Data Input'!B100 -> 0 | C14: ='Data Input'!C100 -> 0
A15: Other interest-bearing liabilities | B15: ='Data Input'!B101 -> 0 | C15: ='Data Input'!C101 -> 0
A16: Total Debt (= Adjusted Debt for the standalone SPV perimeter, CORE Section 9.3) | B16: =SUMIF(C8:C15,"Debt",B8:B15) -> 21500
A17: Instruments classified as equity (carried into Tangible Net Worth below) | B17: =SUMIF(C8:C15,"Equity",B8:B15) -> 1000
A19: Tangible Net Worth build (CORE Section 9.3)
A20: Paid-up equity share capital | B20: ='Data Input'!B106 -> 6000
A21: Securities premium | B21: ='Data Input'!B107 -> 2000
A22: Free reserves | B22: ='Data Input'!B108 -> 500
A23: Add: instruments meeting the equity-treatment test | B23: =B17 -> 1000
A24: Less: intangible assets | B24: ='Data Input'!B110 -> 100
A25: Less: revaluation reserves | B25: ='Data Input'!B111 -> 0
A26: Less: accumulated losses | B26: ='Data Input'!B112 -> 52
A27: Less: deferred revenue expenditure not written off | B27: ='Data Input'!B113 -> 0
A28: Tangible Net Worth | B28: =SUM(B20:B23)-SUM(B24:B27) -> 9348
A30: Coverage and leverage
A31: Project cash flow from operations (CFO) | B31: ='Data Input'!B118 -> 3548
A32: Project CFO / Adjusted Debt < auto, decimal fraction | B32: =IF(OR(B16="",B16=0),"",B31/B16) -> 0.16502326
A33: Gearing — Total Debt / Tangible Net Worth (x) | B33: =IF(COUNT(B20:B22)=0,"",IF(B28<=0,0,B16/B28)) -> 2.2999572
A34: CORE v2.0 Section 5.2 is titled "Gearing — Total Debt / Tangible Net Worth" and that is the single governing definition. v1.0 titled the factor "Gearing — Debt: Equity" with tiers labelled 65:35, 70:30, 75:25 and 80:20, while Section 9.2 defined it as Total Debt / Tangible Net Worth — two different ratios, since TNW excludes intangibles and treats revaluation reserves differently from book equity. The x-multiple equivalents of those ratio labels are retained in CORE for orientation only and hold only where TNW equals book equity.
A35: =IF(COUNT(B20:B22)=0,"",IF(B28<=0,"WARN — tangible net worth is nil or negative; CORE Section 5.2 scores 0 and the result is flagged (validation rule V9)",""))
A37: Liquidity — DSRA / reserve cover (CORE Section 5.3)
A38: Total DSRA or equivalent reserve balance | B38: ='Data Input'!B124 -> 1350
A39: Of which encumbered — pledged, margined or earmarked for another purpose | B39: ='Data Input'!B125 -> 0
A40: Other available cash — total | B40: ='Data Input'!B126 -> 250
A41: Of which encumbered | B41: ='Data Input'!B127 -> 0
A42: Average monthly debt service (interest + principal) | B42: ='Data Input'!B128 -> 180
A43: Unencumbered DSRA | B43: =IF(B38="","",MAX(0,B38-B39)) -> 1350
...

Sheet Validation
A1: VALIDATION — INTERNAL CONSISTENCY CHECKS
A2: Implements CORE v3.0 Section 10.1. Section 10.1.1 states WHEN these run: Stage 1 critical nulls, Stage 2 non-critical nulls, Stage 3 these checks, Stage 4 scoring, Stage 5 engine assertions. A rule runs ONLY where every operand it needs is populated; otherwise it returns "Not Evaluated" and does not block. Not Evaluated does not itself reduce confidence — the underlying null already does.
A3: Rules V3, V11, V12, V13 and A3 depend on inputs held in Key Input Template 1 and are evaluated by the engine, not by this workbook. They are listed so the full rule set is visible in one place.
A5: INPUT VALIDATIONS — these test the submitted input set
A6: Rule | B6: Check | C6: Result | D6: Classification if failed
A7: V1 | B7: Average DSCR >= Minimum DSCR | C7: =IF(OR('B - Cashflow'!B47="",'B - Cashflow'!B48=""),"Not Evaluated — DSCR schedule incomplete",IF('B - Cashflow'!B48>='B - Cashflow'!B47,"Pass","BLOCK")) -> Pass | D7: Block
A8: V2 | B8: PLCR >= LLCR (remaining project life >= remaining loan life) | C8: =IF(OR('B - Cashflow'!B77="",'B - Cashflow'!B78=""),"Not Evaluated — PLCR/LLCR inputs incomplete",IF('B - Cashflow'!B77>='B - Cashflow'!B78,"Pass","BLOCK")) -> Pass | D8: Block
A9: V3 | B9: Offtaker contracted shares (four individual plus the aggregated line) sum to 1.0000 +/- 0.0100 | C9: Engine — Template 1 Section N | D9: Block
A10: V6 | B10: Where a net-cash-accrual CFADS series is supplied, it agrees with the direct build within 2% IN EVERY PERIOD, tested period by period | C10: =IF('B - Cashflow'!C63="","Not applicable — single route used",IF(MAX('Data Input'!E16:E45)<=0.02,"Pass","BLOCK — at least one period exceeds 2%")) -> Not applicable — single route used | D10: Block
A11: V7 | B11: Encumbered DSRA <= total DSRA balance | C11: =IF('C - Financial'!B38="","Not Evaluated — DSRA not entered",IF('C - Financial'!B39<='C - Financial'!B38,"Pass","BLOCK")) -> Pass | D11: Block
A12: V7a | B12: Encumbered other cash <= total other cash [NEW in v3.0 — v2.0 checked DSRA encumbrance only] | C12: =IF('C - Financial'!B40="","Not Evaluated — other cash not entered",IF('C - Financial'!B41<='C - Financial'!B40,"Pass","BLOCK")) -> Pass | D12: Block
A13: V8 | B13: Minimum DSCR < 1.00x coexisting with PLCR >= 2.00x — close to incoherent | C13: =IF(OR('B - Cashflow'!B47="",'B - Cashflow'!B77=""),"Not Evaluated",IF(AND('B - Cashflow'!B47<1,'B - Cashflow'!B77>=2),"WARN","Pass")) -> Pass | D13: Warn
A14: V8a | B14: Minimum DSCR scores 0 points but the coverage floor has NOT triggered — reachable only where the merchant adjustment applies, since the floor is absolute at 1.00x [NEW in v3.0, QA finding M1] | C14: =IF(OR('B - Cashflow'!B47="",'B - Cashflow'!I84=""),"Not Evaluated",IF(AND('B - Cashflow'!I84=0,'B - Cashflow'!B47>=1),"WARN — 0 of 15 points on Minimum DSCR without a band cap; merchant-adjusted threshold","Pass")) -> Pass | D14: Warn
A15: V9 | B15: Tangible net worth is nil or negative | C15: =IF(COUNT('C - Financial'!B20:B22)=0,"Not Evaluated — net worth build not entered",IF('C - Financial'!B28<=0,"WARN — Section 5.2 SCORES 0 (not null); result flagged","Pass")) -> Pass | D15: Warn
A16: V11 | B16: Operating project with COD date later than the calculation date | C16: Engine — Template 1 Section A.1 | D16: Block
A17: V12 | B17: Any offtaker rating, discount rate or ALMM parameter flagged stale | C17: Engine — Template 1 Sections A.5 and N | D17: Warn
A18: V13 | B18: Fields captured in both templates agree: technology_type, calculation_date. Merchant exposure is derived and never entered, so no comparison arises. [NEW in v3.0, QA finding M8] | C18: Engine — Template 1 vs Data Input B6:B7 | D18: Block
A19: V14 | B19: Every instrument with a non-zero amount carries a Debt or Equity treatment [NEW in v3.0, QA finding M14] | C19: =IF(COUNT('Data Input'!B94:B101)=0,"Not Evaluated — debt build not entered",IF(SUMPRODUCT(('Data Input'!B94:B101<>"")*('Data Input'!C94:C101=""))>0,"BLOCK — an instrument carries an amount with no treatment","Pass")) -> Pass | D19: Block
A21: ENGINE ASSERTIONS — these test the engine's own arithmetic, not the user's input
A22: A failure is an implementation defect and must halt the response, not be shown as a data problem. v2.0 listed these as V4, V5 and V10 alongside the input validations, which implied a user could clear them by correcting data. They cannot (QA finding m7).
A23: Rule | B23: Assertion | C23: Result | D23: Classification if failed
A24: A1 | B24: Sum of the four block sub-scores equals the raw score [was V4] | C24: Engine | D24: Halt — implementation defect
A25: A2 | B25: Raw score <= 115 and each block sub-score <= its maximum (35 / 35 / 25 / 20) [was V5] | C25: =IF(AND(OR('B - Cashflow'!B88="",'B - Cashflow'!B88<=35),OR('C - Financial'!B55="",'C - Financial'!B55<=25)),"Pass (Blocks B and C only; A and D are engine-side)","HALT") -> Pass (Blocks B and C only; A and D are engine-side) | D25: Halt — implementation defect
A26: A3 | B26: Where derived merchant exposure > 0.2500, the +0.20x shift is present in the Section 4.1 and 4.2 threshold lookups actually used [was V10] | C26: Engine | D26: Halt — implementation defect
A27: A4 | B27: Where a cap binds, the reported post-notching score is identical to the score the same inputs produce with the cap suppressed [NEW in v3.0] | C27: Engine | D27: Halt — implementation defect
A29: SHEET-LEVEL CHECKS
A30: P90 attestation satisfied (CORE Section 9.5 — attestation is the only route) | B30: ='Data Input'!B58 -> Satisfied
A31: Threshold set resolved from technology type (CORE Section 4.0) | B31: ='Data Input'!B9 -> Set W
A32: Coverage floor status (CORE Section 8.3 — absolute at 1.00x, never merchant-adjusted) | B32: ='Data Input'!B88 -> Coverage floor not triggered
A33: Debt years populated in the DSCR schedule | B33: ='Data Input'!B50 -> 14
A34: Total Debt reconciles to the instrument build (CORE Section 9.3) | B34: =IF(COUNT('Data Input'!B94:B101)=0,"Not Evaluated — debt build not entered",IF(ROUND(SUM('Data Input'!B94:B101),2)=ROUND('Data Input'!B102+'Data Input'!B103,2),"Pass","BLOCK — an instrument amount is classified as neither Debt nor Equity")) -> Pass
A35: ^ v2.0 wrote this check as IF(B16=SUMIF(C8:C15,"Debt",B8:B15)) — comparing Total Debt to its own defining formula, so it always passed. The real risk it should have caught, an instrument with an amount and a blank treatment being silently excluded from BOTH Total Debt and Tangible Net Worth, was unguarded (QA finding M14).
